Workbook
Name \0: #REF!
Name \0: #REF!
Name \0: #REF!
Name \0: #REF!
Name \a: #REF!
Name \a: #REF!
Name \a: #REF!
Name \a: #REF!
Name \CA: #REF!
Name \CA: #REF!
Name \CO: #REF!
Name \CO: #REF!
Name \Convergence: 1.79769313486231E+59
Name \d: #REF!
Name \d: #REF!
Name \d: #REF!
Name \d: #REF!
Name \e: #REF!
Name \e: #REF!
Name \e: #REF!
Name \e: #REF!
Name \f: #REF!
Name \f: #REF!
Name \f: #REF!
Name \f: #REF!
Name \g: #REF!
Name \g: #REF!
Name \h: #REF!
Name \h: #REF!
Name \I: #REF!
Name \I: #REF!
Name \IterationCount: 0
Name \m: #REF!
Name \m: #REF!
Name \p: #REF!
Name \p: #REF!
Name \R: #REF!
Name \R: #REF!
Name \s: #REF!
Name \s: #REF!
Name \t: #REF!
Name \t: #REF!
Name \u: #REF!
Name \u: #REF!
Name \W: #REF!
Name \W: #REF!
Name \WorstStream: " "
Name \y: #REF!
Name \y: #REF!
Name \y: #REF!
Name \y: #REF!
Name _____T2: #REF!
Name _____T2: #REF!
Name _____T2: #REF!
Name _____T2: #REF!
Name ____aux10: #REF!
Name ____aux10: #REF!
Name ____aux10: #REF!
Name ____aux10: #REF!
Name ____aux3: #REF!

Sheet Baseline BoQ
A1: Section | B1: Bill No. | C1: Materials Code | D1: Item No. | E1: Pay Ref | F1: Description | G1: Unit | H1: Contract Quantity | I1: Contract Rate | J1: Contract Amount | K1: 1
A2: Section 1 Preliminaries | B2: Bill No. 1: Fixed Charge Items | F2: SECTION NO. 1
A3: Section 1 Preliminaries | B3: Bill No. 1: Fixed Charge Items | E3: SANS 1200A | F3: PRELIMINARY AND GENERAL
A4: Section 1 Preliminaries | B4: Bill No. 1: Fixed Charge Items | F4: (Applicable to the whole of the Works)
A5: Section 1 Preliminaries | B5: Bill No. 1: Fixed Charge Items | F5: BILL NO. 1
A6: Section 1 Preliminaries | B6: Bill No. 1: Fixed Charge Items | E6: 8.3 | F6: FIXED CHARGE ITEMS
A7: Section 1 Preliminaries | B7: Bill No. 1: Fixed Charge Items | F7: PREAMBLE
A8: Section 1 Preliminaries | B8: Bill No. 1: Fixed Charge Items | F8: A detailed breakdown of the Preliminaries and General costs should be submitted with this tender
A9: Section 1 Preliminaries | B9: Bill No. 1: Fixed Charge Items | D9: A | E9: 8.3.1 | F9: Contractual requirements | G9: SUM | H9: 1 | I9: 500000 | J9: =H9*I9 -> 500000
A10: Section 1 Preliminaries | B10: Bill No. 1: Fixed Charge Items | E10: 8.3.2.2 | F10: Facilities for Contractor
A11: Section 1 Preliminaries | B11: Bill No. 1: Fixed Charge Items | D11: B | E11: 8.3.2.2.a) | F11: Offices and storage sheds | G11: SUM | H11: 1 | I11: 30000 | J11: =H11*I11 -> 30000
A12: Section 1 Preliminaries | B12: Bill No. 1: Fixed Charge Items | D12: C | E12: 8.3.2.2.b) | F12: Workshops | G12: SUM | H12: 1 | I12: 10000 | J12: =H12*I12 -> 10000
A13: Section 1 Preliminaries | B13: Bill No. 1: Fixed Charge Items | D13: D | E13: 8.3.2.2.c) | F13: Laboratories. | G13: Sum | H13: 1 | I13: 10000 | J13: =I13*H13 -> 10000
A14: Section 1 Preliminaries | B14: Bill No. 1: Fixed Charge Items | D14: E | E14: 8.3.2.2.d) | F14: Living accommodation. | G14: Sum | H14: 1 | I14: 20000 | J14: =I14*H14 -> 20000
A15: Section 1 Preliminaries | B15: Bill No. 1: Fixed Charge Items | D15: F | E15: 8.3.2.2.e) | F15: Ablution and latrine facilities. | G15: Sum | H15: 1 | I15: 20000 | J15: =I15*H15 -> 20000
A16: Section 1 Preliminaries | B16: Bill No. 1: Fixed Charge Items | D16: G | E16: 8.3.2.2.f) | F16: Tools and equipment | G16: SUM | H16: 1 | I16: 20000 | J16: =H16*I16 -> 20000
A17: Section 1 Preliminaries | B17: Bill No. 1: Fixed Charge Items | D17: H | E17: 8.3.2.2.g) | F17: Water supplies, electric power, communications, dealing with water, and access | G17: SUM | H17: 1 | I17: 15000 | J17: =H17*I17 -> 15000
A18: Section 1 Preliminaries | B18: Bill No. 1: Fixed Charge Items | D18: J | E18: 8.3.2.2.j) | F18: Plant. | G18: SUM | H18: 1 | I18: 25000 | J18: =I18*H18 -> 25000
A19: Section 1 Preliminaries | B19: Bill No. 1: Fixed Charge Items | D19: K | F19: Medicals and inductions | G19: SUM | H19: 1 | I19: 20000 | J19: =I19*H19 -> 20000
A20: Section 1 Preliminaries | B20: Bill No. 1: Fixed Charge Items | D20: L | F20: Fencing of laydown area | G20: SUM | H20: 1 | I20: 55933.13 | J20: =I20*H20 -> 55933.13
A21: Section 1 Preliminaries | B21: Bill No. 1: Fixed Charge Items | D21: M | E21: 8.3.3 | F21: Other fixed charge obligations | G21: SUM | H21: 1 | I21: 5000 | J21: =H21*I21 -> 5000
A22: Section 1 Preliminaries | B22: Bill No. 1: Fixed Charge Items | D22: N | E22: 8.3.4 | F22: Removal of site establishment | G22: SUM | H22: 1 | I22: 15000 | J22: =H22*I22 -> 15000
A23: Section 1 Preliminaries | B23: Bill No. 2: Time Related Items | F23: SECTION NO. 1
A24: Section 1 Preliminaries | B24: Bill No. 2: Time Related Items | E24: SANS 1200A | F24: PRELIMINARY AND GENERAL
A25: Section 1 Preliminaries | B25: Bill No. 2: Time Related Items | F25: (Applicable to the whole of the Works)
A26: Section 1 Preliminaries | B26: Bill No. 2: Time Related Items | F26: BILL NO. 2
A27: Section 1 Preliminaries | B27: Bill No. 2: Time Related Items | E27: 8.4 | F27: TIME RELATED ITEMS
A28: Section 1 Preliminaries | B28: Bill No. 2: Time Related Items | F28: PREAMBLE
A29: Section 1 Preliminaries | B29: Bill No. 2: Time Related Items | F29: A detailed breakdown of the Preliminaries and General costs should be submitted with this tender
A30: Section 1 Preliminaries | B30: Bill No. 2: Time Related Items | D30: A | E30: 8.4.1 | F30: Contractual requirements | G30: SUM | H30: 1 | I30: 100000 | J30: =H30*I30 -> 100000
A31: Section 1 Preliminaries | B31: Bill No. 2: Time Related Items | E31: 8.4.2 | F31: Operation and Maintenance of Facilities on Site, for Duration of Construction, (unless otherwise stated)
A32: Section 1 Preliminaries | B32: Bill No. 2: Time Related Items | E32: 8.4.2.2 | F32: Facilities for Contractor
A33: Section 1 Preliminaries | B33: Bill No. 2: Time Related Items | D33: B | E33: 8.4.2.2.a) | F33: Offices and storage sheds | G33: SUM | H33: 1 | I33: 30000 | J33: =H33*I33 -> 30000
A34: Section 1 Preliminaries | B34: Bill No. 2: Time Related Items | D34: C | E34: 8.4.2.2.b) | F34: Workshops | G34: SUM | H34: 1 | I34: 15000 | J34: =H34*I34 -> 15000
A35: Section 1 Preliminaries | B35: Bill No. 2: Time Related Items | D35: D | E35: 8.4.2.2.c) | F35: Laboratories | G35: SUM | H35: 1 | I35: 15000 | J35: =H35*I35 -> 15000
A36: Section 1 Preliminaries | B36: Bill No. 2: Time Related Items | D36: E | E36: 8.4.2.2.d) | F36: Living accommodation | G36: SUM | H36: 1 | I36: 30000 | J36: =H36*I36 -> 30000
A37: Section 1 Preliminaries | B37: Bill No. 2: Time Related Items | D37: F | E37: 8.4.2.2.e) | F37: Ablution and latrine facilities | G37: SUM | H37: 1 | I37: 30000 | J37: =H37*I37 -> 30000
A38: Section 1 Preliminaries | B38: Bill No. 2: Time Related Items | D38: G | E38: 8.4.2.2.f) | F38: Tools and equipment | G38: SUM | H38: 1 | I38: 20000 | J38: =H38*I38 -> 20000
A39: Section 1 Preliminaries | B39: Bill No. 2: Time Related Items | D39: H | E39: 8.4.2.2.g) | F39: Water supplies, electric power, communications, dealing with water, and access | G39: SUM | H39: 1 | I39: 20000 | J39: =H39*I39 -> 20000
A40: Section 1 Preliminaries | B40: Bill No. 2: Time Related Items | D40: J | E40: 8.4.2.2.j) | F40: Plant | G40: SUM | H40: 1 | I40: 60000 | J40: =H40*I40 -> 60000
...

Sheet Output BoQ
A1: Structure | B1: Bill No. | C1: Trade Code | D1: Accounts Code | E1: Specification Code | F1: Item No. | G1: Pay Ref | H1: Description | I1: Unit | J1: Contract Quantity | K1: Contract Rate | L1: Contract Amount | M1: Progress Quantity | N1: Forecast Quantity | O1: New Materials Rate | P1: Progress Amount | Q1: Forecast Amount
A2: Section 1 Preliminaries | B2: Bill No. 1: Fixed Charge Items | H2: SECTION NO. 1
A3: Section 1 Preliminaries | B3: Bill No. 1: Fixed Charge Items | G3: SANS 1200A | H3: PRELIMINARY AND GENERAL
A4: Section 1 Preliminaries | B4: Bill No. 1: Fixed Charge Items | H4: (Applicable to the whole of the Works)
A5: Section 1 Preliminaries | B5: Bill No. 1: Fixed Charge Items | H5: BILL NO. 1
A6: Section 1 Preliminaries | B6: Bill No. 1: Fixed Charge Items | G6: 8.3 | H6: FIXED CHARGE ITEMS
A7: Section 1 Preliminaries | B7: Bill No. 1: Fixed Charge Items | H7: PREAMBLE
A8: Section 1 Preliminaries | B8: Bill No. 1: Fixed Charge Items | H8: A detailed breakdown of the Preliminaries and General costs should be submitted with this tender
A9: Section 1 Preliminaries | B9: Bill No. 1: Fixed Charge Items | F9: A | G9: 8.3.1 | H9: Contractual requirements | I9: SUM | J9: 1 | K9: 500000 | L9: =J9*K9 -> 500000 | M9: 1 | N9: 1 | O9: 500000 | P9: =O9*M9 -> 500000 | Q9: =O9*N9 -> 500000
A10: Section 1 Preliminaries | B10: Bill No. 1: Fixed Charge Items | G10: 8.3.2.2 | H10: Facilities for Contractor | P10: =O10*M10 -> 0 | Q10: =O10*N10 -> 0
A11: Section 1 Preliminaries | B11: Bill No. 1: Fixed Charge Items | F11: B | G11: 8.3.2.2.a) | H11: Offices and storage sheds | I11: SUM | J11: 1 | K11: 30000 | L11: =J11*K11 -> 30000 | M11: 1 | N11: 1 | O11: 30000 | P11: =O11*M11 -> 30000 | Q11: =O11*N11 -> 30000
A12: Section 1 Preliminaries | B12: Bill No. 1: Fixed Charge Items | F12: C | G12: 8.3.2.2.b) | H12: Workshops | I12: SUM | J12: 1 | K12: 10000 | L12: =J12*K12 -> 10000 | M12: 1 | N12: 1 | O12: 10000 | P12: =O12*M12 -> 10000 | Q12: =O12*N12 -> 10000
A13: Section 1 Preliminaries | B13: Bill No. 1: Fixed Charge Items | F13: D | G13: 8.3.2.2.c) | H13: Laboratories. | I13: Sum | J13: 1 | K13: 10000 | L13: =K13*J13 -> 10000 | M13: 1 | N13: 1 | O13: 10000 | P13: =O13*M13 -> 10000 | Q13: =O13*N13 -> 10000
A14: Section 1 Preliminaries | B14: Bill No. 1: Fixed Charge Items | F14: E | G14: 8.3.2.2.d) | H14: Living accommodation. | I14: Sum | J14: 1 | K14: 20000 | L14: =K14*J14 -> 20000 | M14: 1 | N14: 1 | O14: 20000 | P14: =O14*M14 -> 20000 | Q14: =O14*N14 -> 20000
A15: Section 1 Preliminaries | B15: Bill No. 1: Fixed Charge Items | F15: F | G15: 8.3.2.2.e) | H15: Ablution and latrine facilities. | I15: Sum | J15: 1 | K15: 20000 | L15: =K15*J15 -> 20000 | M15: 1 | N15: 1 | O15: 20000 | P15: =O15*M15 -> 20000 | Q15: =O15*N15 -> 20000
A16: Section 1 Preliminaries | B16: Bill No. 1: Fixed Charge Items | F16: G | G16: 8.3.2.2.f) | H16: Tools and equipment | I16: SUM | J16: 1 | K16: 20000 | L16: =J16*K16 -> 20000 | M16: 1 | N16: 1 | O16: 20000 | P16: =O16*M16 -> 20000 | Q16: =O16*N16 -> 20000
A17: Section 1 Preliminaries | B17: Bill No. 1: Fixed Charge Items | F17: H | G17: 8.3.2.2.g) | H17: Water supplies, electric power, communications, dealing with water, and access | I17: SUM | J17: 1 | K17: 15000 | L17: =J17*K17 -> 15000 | M17: 1 | N17: 1 | O17: 15000 | P17: =O17*M17 -> 15000 | Q17: =O17*N17 -> 15000
A18: Section 1 Preliminaries | B18: Bill No. 1: Fixed Charge Items | F18: J | G18: 8.3.2.2.j) | H18: Plant. | I18: SUM | J18: 1 | K18: 25000 | L18: =K18*J18 -> 25000 | M18: 1 | N18: 1 | O18: 25000 | P18: =O18*M18 -> 25000 | Q18: =O18*N18 -> 25000
A19: Section 1 Preliminaries | B19: Bill No. 1: Fixed Charge Items | F19: K | H19: Medicals and inductions | I19: SUM | J19: 1 | K19: 20000 | L19: =K19*J19 -> 20000 | M19: 1 | N19: 1 | O19: 20000 | P19: =O19*M19 -> 20000 | Q19: =O19*N19 -> 20000
A20: Section 1 Preliminaries | B20: Bill No. 1: Fixed Charge Items | F20: L | H20: Fencing of laydown area | I20: SUM | J20: 1 | K20: 55933.13 | L20: =K20*J20 -> 55933.13 | M20: 1 | N20: 1 | O20: 55933.13 | P20: =O20*M20 -> 55933.13 | Q20: =O20*N20 -> 55933.13
A21: Section 1 Preliminaries | B21: Bill No. 1: Fixed Charge Items | F21: M | G21: 8.3.3 | H21: Other fixed charge obligations | I21: SUM | J21: 1 | K21: 5000 | L21: =J21*K21 -> 5000 | M21: 1 | N21: 1 | O21: 5000 | P21: =O21*M21 -> 5000 | Q21: =O21*N21 -> 5000
A22: Section 1 Preliminaries | B22: Bill No. 1: Fixed Charge Items | F22: N | G22: 8.3.4 | H22: Removal of site establishment | I22: SUM | J22: 1 | K22: 15000 | L22: =J22*K22 -> 15000 | M22: 1 | N22: 1 | O22: 15000 | P22: =O22*M22 -> 15000 | Q22: =O22*N22 -> 15000
A23: Section 1 Preliminaries | B23: Bill No. 2: Time Related Items | H23: SECTION NO. 1 | P23: =O23*M23 -> 0 | Q23: =O23*N23 -> 0
A24: Section 1 Preliminaries | B24: Bill No. 2: Time Related Items | G24: SANS 1200A | H24: PRELIMINARY AND GENERAL | P24: =O24*M24 -> 0 | Q24: =O24*N24 -> 0
A25: Section 1 Preliminaries | B25: Bill No. 2: Time Related Items | H25: (Applicable to the whole of the Works) | P25: =O25*M25 -> 0 | Q25: =O25*N25 -> 0
A26: Section 1 Preliminaries | B26: Bill No. 2: Time Related Items | H26: BILL NO. 2 | P26: =O26*M26 -> 0 | Q26: =O26*N26 -> 0
A27: Section 1 Preliminaries | B27: Bill No. 2: Time Related Items | G27: 8.4 | H27: TIME RELATED ITEMS | P27: =O27*M27 -> 0 | Q27: =O27*N27 -> 0
A28: Section 1 Preliminaries | B28: Bill No. 2: Time Related Items | H28: PREAMBLE | P28: =O28*M28 -> 0 | Q28: =O28*N28 -> 0
A29: Section 1 Preliminaries | B29: Bill No. 2: Time Related Items | H29: A detailed breakdown of the Preliminaries and General costs should be submitted with this tender | P29: =O29*M29 -> 0 | Q29: =O29*N29 -> 0
A30: Section 1 Preliminaries | B30: Bill No. 2: Time Related Items | F30: A | G30: 8.4.1 | H30: Contractual requirements | I30: SUM | J30: 1 | K30: 100000 | L30: =J30*K30 -> 100000 | M30: 1 | N30: 1 | O30: 100000 | P30: =O30*M30 -> 100000 | Q30: =O30*N30 -> 100000
A31: Section 1 Preliminaries | B31: Bill No. 2: Time Related Items | G31: 8.4.2 | H31: Operation and Maintenance of Facilities on Site, for Duration of Construction, (unless otherwise stated) | P31: =O31*M31 -> 0 | Q31: =O31*N31 -> 0
A32: Section 1 Preliminaries | B32: Bill No. 2: Time Related Items | G32: 8.4.2.2 | H32: Facilities for Contractor | P32: =O32*M32 -> 0 | Q32: =O32*N32 -> 0
A33: Section 1 Preliminaries | B33: Bill No. 2: Time Related Items | F33: B | G33: 8.4.2.2.a) | H33: Offices and storage sheds | I33: SUM | J33: 1 | K33: 30000 | L33: =J33*K33 -> 30000 | M33: 1 | N33: 1 | O33: 30000 | P33: =O33*M33 -> 30000 | Q33: =O33*N33 -> 30000
A34: Section 1 Preliminaries | B34: Bill No. 2: Time Related Items | F34: C | G34: 8.4.2.2.b) | H34: Workshops | I34: SUM | J34: 1 | K34: 15000 | L34: =J34*K34 -> 15000 | M34: 1 | N34: 1 | O34: 15000 | P34: =O34*M34 -> 15000 | Q34: =O34*N34 -> 15000
A35: Section 1 Preliminaries | B35: Bill No. 2: Time Related Items | F35: D | G35: 8.4.2.2.c) | H35: Laboratories | I35: SUM | J35: 1 | K35: 15000 | L35: =J35*K35 -> 15000 | M35: 1 | N35: 1 | O35: 15000 | P35: =O35*M35 -> 15000 | Q35: =O35*N35 -> 15000
A36: Section 1 Preliminaries | B36: Bill No. 2: Time Related Items | F36: E | G36: 8.4.2.2.d) | H36: Living accommodation | I36: SUM | J36: 1 | K36: 30000 | L36: =J36*K36 -> 30000 | M36: 1 | N36: 1 | O36: 30000 | P36: =O36*M36 -> 30000 | Q36: =O36*N36 -> 30000
A37: Section 1 Preliminaries | B37: Bill No. 2: Time Related Items | F37: F | G37: 8.4.2.2.e) | H37: Ablution and latrine facilities | I37: SUM | J37: 1 | K37: 30000 | L37: =J37*K37 -> 30000 | M37: 1 | N37: 1 | O37: 30000 | P37: =O37*M37 -> 30000 | Q37: =O37*N37 -> 30000
A38: Section 1 Preliminaries | B38: Bill No. 2: Time Related Items | F38: G | G38: 8.4.2.2.f) | H38: Tools and equipment | I38: SUM | J38: 1 | K38: 20000 | L38: =J38*K38 -> 20000 | M38: 1 | N38: 1 | O38: 20000 | P38: =O38*M38 -> 20000 | Q38: =O38*N38 -> 20000
A39: Section 1 Preliminaries | B39: Bill No. 2: Time Related Items | F39: H | G39: 8.4.2.2.g) | H39: Water supplies, electric power, communications, dealing with water, and access | I39: SUM | J39: 1 | K39: 20000 | L39: =J39*K39 -> 20000 | M39: 1 | N39: 1 | O39: 20000 | P39: =O39*M39 -> 20000 | Q39: =O39*N39 -> 20000
A40: Section 1 Preliminaries | B40: Bill No. 2: Time Related Items | F40: J | G40: 8.4.2.2.j) | H40: Plant | I40: SUM | J40: 1 | K40: 60000 | L40: =J40*K40 -> 60000 | M40: 1 | N40: 1 | O40: 60000 | P40: =O40*M40 -> 60000 | Q40: =O40*N40 -> 60000
...

Sheet Trade Code
A1: PREFIX | B1: TRADE NAME | C1: TRADE CODE
A2: PRE- | B2: Preliminaries | C2: =A2&B2 -> PRE-Preliminaries
A3: EAR- | B3: Earthworks | C3: =A3&B3 -> EAR-Earthworks
A4: CFR- | B4: Concrete, Formwork & Reinforcement | C4: =A4&B4 -> CFR-Concrete, Formwork & Reinforcement
A5: PRC- | B5: Precast Concrete | C5: =A5&B5 -> PRC-Precast Concrete
A6: MAN- | B6: Masonry | C6: =A6&B6 -> MAN-Masonry
A7: WPR- | B7: Waterproofing | C7: =A7&B7 -> WPR-Waterproofing
A8: ROF- | B8: Roofing Coverings | C8: =A8&B8 -> ROF-Roofing Coverings
A9: CRJ- | B9: Carpentry and Joinery | C9: =A9&B9 -> CRJ-Carpentry and Joinery
A10: CPA- | B10: Ceilings, Partitions & Access Flooring | C10: =A10&B10 -> CPA-Ceilings, Partitions & Access Flooring
A11: FLR- | B11: Floor Coverings, Wall Linings, Etc | C11: =A11&B11 -> FLR-Floor Coverings, Wall Linings, Etc
A12: IRM- | B12: Ironmongery | C12: =A12&B12 -> IRM-Ironmongery
A13: STW- | B13: Structural Steelwork | C13: =A13&B13 -> STW-Structural Steelwork
... A23: EXT- | B23: External Work | C23: =A23&B23 -> EXT-External Work

Sheet Account Code
A1: Number | B1: Name | C1: Account Code
A2: 1001 - | B2: Sales/ Revenue | C2: =A2&B2 -> 1001 - Sales/ Revenue
A3: 1002 - | B3: Cash Deposit | C3: =A3&B3 -> 1002 - Cash Deposit
A4: 2000 - | B4: General | C4: =A4&B4 -> 2000 - General
A5: 2001 - | B5: Materials | C5: =A5&B5 -> 2001 - Materials
A6: 2002 - | B6: Labour | C6: =A6&B6 -> 2002 - Labour
A7: 2003 - | B7: Plant and Equipment | C7: =A7&B7 -> 2003 - Plant and Equipment
A8: 2004 - | B8: Tools | C8: =A8&B8 -> 2004 - Tools
A9: 2005 - | B9: Consumables | C9: =A9&B9 -> 2005 - Consumables
A10: 2006 - | B10: Inventory | C10: =A10&B10 -> 2006 - Inventory
A11: 2007 - | B11: Subcontractor | C11: =A11&B11 -> 2007 - Subcontractor
A12: 2008 - | B12: Other | C12: =A12&B12 -> 2008 - Other
A13: 3000 - | B13: General | C13: =A13&B13 -> 3000 - General
... A37: 4017 - | B37: Other | C37: =A37&B37 -> 4017 - Other

Sheet Specification Code
B1: concrete settings
G2: Quantity per m3 of Concrete | L2: Quantity for Bill Quantity
A3: Trade Code | B3: Concrete Name | C3: Concrete strength | D3: Cement Code | E3: Dand Code | F3: Stone Link | G3: Cement bags | H3: Sand cubes | I3: Stone cubes | J3: Rate/m3 | K3: BoQ Quantity | L3: Cement bags | M3: Sand cubes | N3: Stone cubes
A4: CFR-Concrete, Formwork & Reinforcement | B4: CONC_10 | C4: 10MPa Mix | D4: CFR01-CEM-42.5N | E4: CFR01-SAN-RIV | F4: CFR01-STO-19 | G4: 4.2 | H4: 0.75 | I4: 0.75 | J4: =G4*'Materials Code'!G$2+'Specification Code'!H4*'Materials Code'!G$4+'Specification Code'!I4*'Materials Code'!G$5 -> 1366.8 | K4: 10 | L4: =K4*H4 -> 7.5 | M4: =K4*H4 -> 7.5 | N4: =K4*I4 -> 7.5
A5: CFR-Concrete, Formwork & Reinforcement | B5: CONC_15 | C5: 15MPa Mix | D5: CFR01-CEM-42.5N | E5: CFR01-SAN-RIV | F5: CFR01-STO-19 | G5: 6.2 | H5: 0.7 | I5: 0.8 | J5: =G5*'Materials Code'!G$2+'Specification Code'!H5*'Materials Code'!G$4+'Specification Code'!I5*'Materials Code'!G$5 -> 1624.8 | K5: ='Output BoQ'!J107 -> 14 | L5: =K5*H5 -> 9.8 | M5: =K5*H5 -> 9.8 | N5: =K5*I5 -> 11.2
A6: CFR-Concrete, Formwork & Reinforcement | B6: CONC_20 | C6: 20MPa Mix | D6: CFR01-CEM-42.5N | E6: CFR01-SAN-RIV | F6: CFR01-STO-19 | G6: 7.5 | H6: 0.65 | I6: 0.85 | J6: =G6*'Materials Code'!G$2+'Specification Code'!H6*'Materials Code'!G$4+'Specification Code'!I6*'Materials Code'!G$5 -> 1792.5 | K6: 10 | L6: =K6*H6 -> 6.5 | M6: =K6*H6 -> 6.5 | N6: =K6*I6 -> 8.5
A7: CFR-Concrete, Formwork & Reinforcement | B7: CONC_25 | C7: 25MPa Mix | D7: CFR01-CEM-32.5R | E7: CFR01-SAN-RIV | F7: CFR01-STO-19 | G7: 8.2 | H7: 0.65 | I7: 0.85 | J7: =G7*'Materials Code'!G$2+'Specification Code'!H7*'Materials Code'!G$4+'Specification Code'!I7*'Materials Code'!G$5 -> 1882.8 | K7: 10 | L7: =K7*H7 -> 6.5 | M7: =K7*H7 -> 6.5 | N7: =K7*I7 -> 8.5
A8: CFR-Concrete, Formwork & Reinforcement | B8: CONC_30 | C8: 30MPa Mix | D8: CFR01-CEM-42.5N | E8: CFR01-SAN-RIV | F8: CFR01-STO-19 | G8: 9.8 | H8: 0.6 | I8: 0.9 | J8: =G8*'Materials Code'!G$2+'Specification Code'!H8*'Materials Code'!G$4+'Specification Code'!I8*'Materials Code'!G$5 -> 2089.2 | K8: 10 | L8: =K8*H8 -> 6 | M8: =K8*H8 -> 6 | N8: =K8*I8 -> 9

Sheet Materials Code
A1: Prefix | B1: Trade Code | C1: Material Code | D1: Item Code | E1: Material Variety | F1: Market Spec / Strength | G1: Market Rate | H1: Unit
A2: CFR - | B2: CFR-Concrete, Formwork & Reinforcement | C2: CEM-42.5N | D2: =A2&C2 -> CFR -CEM-42.5N | E2: Portland Cement | F2: 42.5N Structural | G2: 129 | H2: Bag
A3: CFR - | B3: CFR-Concrete, Formwork & Reinforcement | C3: CEM-52.5N | D3: =A3&C3 -> CFR -CEM-52.5N | E3: High Strength Cement | F3: 52.5N (for Columns/Slabs) | G3: 145 | H3: Bag
A4: CFR - | B4: CFR-Concrete, Formwork & Reinforcement | C4: SAN-RIV | D4: =A4&C4 -> CFR -SAN-RIV | E4: River Sand | F4: Sharp/Concreting Sand | G4: 550 | H4: m3
A5: CFR - | B5: CFR-Concrete, Formwork & Reinforcement | C5: STO-19 | D5: =A5&C5 -> CFR -STO-19 | E5: Concrete Stone | F5: 19mm Crushed Aggregate | G5: 550 | H5: m3
A6: CFR - | B6: CFR-Concrete, Formwork & Reinforcement | C6: STO-13 | D6: =A6&C6 -> CFR -STO-13 | E6: Concrete Stone | F6: 13.2mm (for Thin Sections) | H6: m3
A7: CFR - | B7: CFR-Concrete, Formwork & Reinforcement | C7: STO-9.5 | D7: =A7&C7 -> CFR -STO-9.5 | E7: Concrete Stone | F7: 9.5mm (for Rib & Block) | H7: m3
A8: CFR - | B8: CFR-Concrete, Formwork & Reinforcement | C8: CON-CUR | D8: =A8&C8 -> CFR -CON-CUR | E8: Curing Compound | F8: Prescribed Curing Liquid | H8: 25L
A9: CFR - | B9: CFR-Concrete, Formwork & Reinforcement | C9: CON-GRO-NS | D9: =A9&C9 -> CFR -CON-GRO-NS | E9: Non-Shrink Grout | F9: For Column Bases/Beds | H9: 25kg
A10: CFR - | B10: CFR-Concrete, Formwork & Reinforcement | C10: FRM-PLY-21 | D10: =A10&C10 -> CFR -FRM-PLY-21 | E10: Shutterboard | F10: 21mm FHP Brown Film | H10: Sheet
A11: CFR - | B11: CFR-Concrete, Formwork & Reinforcement | C11: FRM-TIM-S5 | D11: =A11&C11 -> CFR -FRM-TIM-S5 | E11: Shutter Timber | F11: 38 x 114mm S5 Structural | H11: Lm
A12: CFR - | B12: CFR-Concrete, Formwork & Reinforcement | C12: FRM-OIL-RE | D12: =A12&C12 -> CFR -FRM-OIL-RE | E12: Release Agent | F12: Shutter Oil (Chemical) | H12: 20L
A13: CFR - | B13: CFR-Concrete, Formwork & Reinforcement | C13: FRM-TIE-RD | D13: =A13&C13 -> CFR -FRM-TIE-RD | E13: Tie Rods | F13: High Tensile (for Walls/Columns) | H13: m
A14: CFR - | B14: CFR-Concrete, Formwork & Reinforcement | C14: FRM-TIE-CO | D14: =A14&C14 -> CFR -FRM-TIE-CO | E14: Ferrules/Cones | F14: Plastic Sleeves for Tie Rods | H14: Each
A15: CFR - | B15: CFR-Concrete, Formwork & Reinforcement | C15: FRM-CHM-ST | D15: =A15&C15 -> CFR -FRM-CHM-ST | E15: Chamfer Strip | F15: 20mm x 20mm PVC | H15: Lm
A16: CFR - | B16: CFR-Concrete, Formwork & Reinforcement | C16: Y-REBAR-VAR | D16: =A16&C16 -> CFR -Y-REBAR-VAR | E16: High Yield Steel | F16: 450MPa (Y10, Y12, Y16, Y20) | H16: Ton/ Kg
A17: CFR - | B17: CFR-Concrete, Formwork & Reinforcement | C17: R-REBAR-VAR | D17: =A17&C17 -> CFR -R-REBAR-VAR | E17: Mild Steel Rods | F17: 250MPa (R6, R8, R10) | H17: Ton/ Kg
... A22: CFR - | B22: CFR-Concrete, Formwork & Reinforcement | C22: BIND-WIRE | D22: =A22&C22 -> CFR -BIND-WIRE | E22: Binding Wire | F22: 1.6mm Annealed | H22: 50kg
A23: MAN - | B23: MAN-Masonry | C23: NFP-230 | D23: =A23&C23 -> MAN -NFP-230 | E23: Common Clay Brick | F23: 222x106x73mm (Double skin) | H23: 1000
A24: MAN - | B24: MAN-Masonry | C24: NFP-115 | D24: =A24&C24 -> MAN -NFP-115 | E24: Common Clay Brick | F24: 222x106x73mm (Single skin) | H24: 1000
A25: MAN - | B25: MAN-Masonry | C25: FBX-230 | D25: =A25&C25 -> MAN -FBX-230 | E25: Face Brick Extra | F25: 222x106x73mm (High Grade) | H25: 1000
A26: MAN - | B26: MAN-Masonry | C26: CEM-STD | D26: =A26&C26 -> MAN -CEM-STD | E26: Cement Brick | F26: Standard 7MPa | H26: 1000
A27: MAN - | B27: MAN-Masonry | C27: BLOCK-M140 | D27: =A27&C27 -> MAN -BLOCK-M140 | E27: Hollow Block | F27: 390x140x190mm | H27: Each
A28: MAN - | B28: MAN-Masonry | C28: BLOCK-M90 | D28: =A28&C28 -> MAN -BLOCK-M90 | E28: Hollow Block | F28: 390x90x190mm | H28: Each
A29: MAN - | B29: MAN-Masonry | C29: BLOCK-U140 | D29: =A29&C29 -> MAN -BLOCK-U140 | E29: U-Block Lintel | F29: For 140mm Block walls | H29: Each
A30: MAN - | B30: MAN-Masonry | C30: CEM-PORT-42.4N | D30: =A30&C30 -> MAN -CEM-PORT-42.4N | E30: Portland Cement | F30: 42.5N Strength | H30: Bag
A31: MAN - | B31: MAN-Masonry | C31: BUILD-LIME | D31: =A31&C31 -> MAN -BUILD-LIME | E31: Building Lime | F31: Hydrated Mortar Lime | H31: Bag
A32: MAN - | B32: MAN-Masonry | C32: BUILD-SAND | D32: =A32&C32 -> MAN -BUILD-SAND | E32: Building Sand | F32: Screened Pit/River Sand | H32: m3
A33: MAN - | B33: MAN-Masonry | C33: MOR-PIGM | D33: =A33&C33 -> MAN -MOR-PIGM | E33: Mortar Pigment | F33: Black/Red (for Facebrick) | H33: kg
A34: MAN - | B34: MAN-Masonry | C34: BRK-FOR-75 | D34: =A34&C34 -> MAN -BRK-FOR-75 | E34: Brickforce | F34: 75mm Galvanized | H34: 20m
A35: MAN - | B35: MAN-Masonry | C35: BRK-FOR-150 | D35: =A35&C35 -> MAN -BRK-FOR-150 | E35: Brickforce | F35: 150mm Galvanized | H35: 20m
A36: MAN - | B36: MAN-Masonry | C36: HOOP-32 | D36: =A36&C36 -> MAN -HOOP-32 | E36: Hoop Iron Tie | F36: 32 x 1.6mm (Roof/Wall Ties) | H36: 30m
A37: MAN - | B37: MAN-Masonry | C37: WALL-TIE-C | D37: =A37&C37 -> MAN -WALL-TIE-C | E37: Wall Tie | F37: Crimped Wire (5 per m2) | H37: Each
A38: MAN - | B38: MAN-Masonry | C38: Y10-REBAR | D38: =A38&C38 -> MAN -Y10-REBAR | E38: High Yield Steel | F38: 10mm Bars (for Arches/Piers) | H38: Ton
... A156: FLR - | B156: FLR-Floor Coverings, Wall Linings, Etc | C156: ACC-EDG-STL | D156: =A156&C156 -> FLR -ACC-EDG-STL | E156: Edge Strips | F156: Aluminum Transition/Nosing | H156: Each
A157: IRM - | B157: IRM-Ironmongery | C157: HNG-BUTT | E157: Butt Hinges | F157: 100mm Stainless Steel (Pair) | H157: Pair
A158: IRM - | B158: IRM-Ironmongery | C158: HNG-SPR | E158: Floor Spring | F158: Double Action Hydraulic | H158: Set
A159: IRM - | B159: IRM-Ironmongery | C159: HND-LEV | E159: Lever Handle | F159: S/S Return-to-door (Standard) | H159: Set
A160: IRM - | B160: IRM-Ironmongery | C160: HND-PUL | E160: Pull Handle | F160: 300mm D-Handle (Alternative) | H160: Each
A161: IRM - | B161: IRM-Ironmongery | C161: HK-HAT | E161: Hat & Coat Hook | F161: Single Prong S/S | H161: Each
...
